<mujoco model="4-DoF Arm">
    <compiler inertiafromgeom="true" angle="degree"/>
    <option timestep="0.005" gravity="0 0 -5" cone="elliptic" jacobian="auto" solver="Newton" impratio="1.0"/>
    <!--  collision="predefined"  -->
    <option>
        <flag gravity="enable" override="enable"/>
    </option>
    <statistic center="0 0 0.6" extent="1"/>
    <default>
        <geom contype="1" conaffinity="1" condim="3"/>
        <joint limited="false" damping="0.5" armature="0.1" stiffness="0" frictionloss="0.1"/>
        <motor gear="1 0 0 0 0 0" ctrllimited="false" ctrlrange="-100 100"/>
    </default>
    <!--  #########################################################################  -->
    <worldbody>
        <!--  Link1  -->
        <body name="link1" pos="0 0 0" euler="0 0 0">
            <joint name="L1" pos="0 0 0" type="hinge" axis="0 0 1" limited="false"/>
            <!--  range="-90 90"  -->
            <geom type="cylinder" pos="0 0 0.25" size="0.15 0.25" rgba="0.3 0.6 0 1"/>
            <geom type="cylinder" pos="0 0 0.05" euler="0 0 0" size="0.16 0.05" rgba="1 0 0.5 1"/>
            <!--  Link2  -->
            <body name="link2" pos="0 0 0.5" euler="90 0 -10">
                <joint name="L2" pos="0 0 0" type="hinge" axis="0 0 1" limited="true" range="-150 150"/>
                <!--  range="-150 5" -->
                <geom type="cylinder" pos="0 0.4 0" euler="-90 0 0" size="0.15 0.4" rgba="0.3 0.6 0 1"/>
                <geom type="cylinder" pos="0 0 0" euler="0 0 0" size="0.1 0.15" rgba="1 0 0.5 1"/>
                <!--  Link3 -->
                <body name="link3" pos="0 0.8 0" euler="0 0 -10">
                    <joint name="L3" pos="0 0 0" type="hinge" axis="0 0 1" limited="true" range="-150 150"/>
                    <!--  range="-5 150" -->
                    <geom type="cylinder" pos="0 0.5 0" euler="-90 0 0" size="0.15 0.5" rgba="0.3 0.6 0 1"/>
                    <geom type="cylinder" pos="0 0 0" euler="0 0 0" size="0.1 0.15" rgba="1 0 0.5 1"/>
                    <!--  Link4 -->
                    <body name="link4" pos="0 1.0 0" euler="0 0 -10">
                        <joint name="L4" pos="0 0 0" type="hinge" axis="0 0 1" limited="true" range="-160 160"/>
                        <geom type="box" pos="0 0.1 0" euler="0 0 0" size="0.1 0.1 0.3" rgba="0.5 0.6 0.3 1"/>
                        <geom type="cylinder" pos="0 0 0" euler="0 0 0" size="0.1 0.15" rgba="1 0 0.5 1"/>
                        <!--  Fingers -->
                        <body name="fingers" pos="0 0.35 0" euler="0 0 0">
                            <!-- <joint name="F1" pos="0 -0.15 -0.15" type="slide" axis="0 0 1" limited="true" range="0 0.15"/>
                            <joint name="F2" pos="0 -0.15 0.15" type="slide" axis="0 0 1" limited="true" range="0 0.15"/> -->
                            <geom type="box" pos="0 0 -0.1" euler="0 0 0" size="0.05 0.15 0.05" rgba="0.5 0.6 0.3 1"/>
                            <geom type="box" pos="0 0 0.1" euler="0 0 0" size="0.05 0.15 0.05" rgba="0.5 0.6 0.3 1"/>
                            <site name="EE" type="sphere" pos="0 0 0" size="0.05" rgba="1 0 0 1"/>
                        </body>
                    </body>
                </body>
            </body>
        </body>
    </worldbody>
    <actuator>
        <motor joint="L1" name="link1" gear="1" ctrllimited="true" ctrlrange="-1193 1193"/>
        <motor joint="L2" name="link2" gear="1" ctrllimited="true" ctrlrange="-1193 1193"/>
        <motor joint="L3" name="link3" gear="1" ctrllimited="true" ctrlrange="-1193 1193"/>
        <motor joint="L4" name="link4" gear="1" ctrllimited="true" ctrlrange="-1193 1193"/>
        <!-- <motor joint="F1" name="finger1" gear="1" ctrllimited="true" ctrlrange="-250 250"/>
        <motor joint="F2" name="finger2" gear="1" ctrllimited="true" ctrlrange="-250 250"/> -->
    </actuator>
</mujoco>